[2024-03-19T16:05:49.722+0000] {taskinstance.py:1979} INFO - Dependencies all met for dep_context=non-requeueable deps ti=<TaskInstance: recalls_etl_v1.get_raw_data manual__2024-03-19T16:05:45.814228+00:00 [queued]>
[2024-03-19T16:05:49.725+0000] {taskinstance.py:1979} INFO - Dependencies all met for dep_context=requeueable deps ti=<TaskInstance: recalls_etl_v1.get_raw_data manual__2024-03-19T16:05:45.814228+00:00 [queued]>
[2024-03-19T16:05:49.726+0000] {taskinstance.py:2193} INFO - Starting attempt 1 of 1
[2024-03-19T16:05:49.731+0000] {taskinstance.py:2217} INFO - Executing <Task(PythonOperator): get_raw_data> on 2024-03-19 16:05:45.814228+00:00
[2024-03-19T16:05:49.739+0000] {standard_task_runner.py:60} INFO - Started process 882 to run task
[2024-03-19T16:05:49.742+0000] {standard_task_runner.py:87} INFO - Running: ['***', 'tasks', 'run', 'recalls_etl_v1', 'get_raw_data', 'manual__2024-03-19T16:05:45.814228+00:00', '--job-id', '6', '--raw', '--subdir', 'DAGS_FOLDER/recalls_etl_v1.py', '--cfg-path', '/tmp/tmpvsxdp3ks']
[2024-03-19T16:05:49.743+0000] {standard_task_runner.py:88} INFO - Job 6: Subtask get_raw_data
[2024-03-19T16:05:49.771+0000] {task_command.py:423} INFO - Running <TaskInstance: recalls_etl_v1.get_raw_data manual__2024-03-19T16:05:45.814228+00:00 [running]> on host b1b6e0a46fce
[2024-03-19T16:05:49.822+0000] {taskinstance.py:2513} INFO - Exporting env vars: AIRFLOW_CTX_DAG_OWNER='***' AIRFLOW_CTX_DAG_ID='recalls_etl_v1' AIRFLOW_CTX_TASK_ID='get_raw_data' AIRFLOW_CTX_EXECUTION_DATE='2024-03-19T16:05:45.814228+00:00' AIRFLOW_CTX_TRY_NUMBER='1' AIRFLOW_CTX_DAG_RUN_ID='manual__2024-03-19T16:05:45.814228+00:00'
[2024-03-19T16:05:49.826+0000] {taskinstance.py:2731} ERROR - Task failed with exception
Traceback (most recent call last):
  File "/home/airflow/.local/lib/python3.8/site-packages/airflow/models/taskinstance.py", line 444, in _execute_task
    result = _execute_callable(context=context, **execute_callable_kwargs)
  File "/home/airflow/.local/lib/python3.8/site-packages/airflow/models/taskinstance.py", line 414, in _execute_callable
    return execute_callable(context=context, **execute_callable_kwargs)
  File "/home/airflow/.local/lib/python3.8/site-packages/airflow/operators/python.py", line 200, in execute
    return_value = self.execute_callable()
  File "/home/airflow/.local/lib/python3.8/site-packages/airflow/operators/python.py", line 217, in execute_callable
    return self.python_callable(*self.op_args, **self.op_kwargs)
  File "/opt/airflow/dags/recalls_etl_v1.py", line 37, in get_recall_data
    response = requests.get(url)
  File "/home/airflow/.local/lib/python3.8/site-packages/requests/api.py", line 73, in get
    return request("get", url, params=params, **kwargs)
  File "/home/airflow/.local/lib/python3.8/site-packages/requests/api.py", line 59, in request
    return session.request(method=method, url=url, **kwargs)
  File "/home/airflow/.local/lib/python3.8/site-packages/requests/sessions.py", line 575, in request
    prep = self.prepare_request(req)
  File "/home/airflow/.local/lib/python3.8/site-packages/requests/sessions.py", line 486, in prepare_request
    p.prepare(
  File "/home/airflow/.local/lib/python3.8/site-packages/requests/models.py", line 368, in prepare
    self.prepare_url(url, params)
  File "/home/airflow/.local/lib/python3.8/site-packages/requests/models.py", line 439, in prepare_url
    raise MissingSchema(
requests.exceptions.MissingSchema: Invalid URL 'data.json': No scheme supplied. Perhaps you meant https://data.json?
[2024-03-19T16:05:49.831+0000] {taskinstance.py:1149} INFO - Marking task as FAILED. dag_id=recalls_etl_v1, task_id=get_raw_data, execution_date=20240319T160545, start_date=20240319T160549, end_date=20240319T160549
[2024-03-19T16:05:49.837+0000] {standard_task_runner.py:107} ERROR - Failed to execute job 6 for task get_raw_data (Invalid URL 'data.json': No scheme supplied. Perhaps you meant https://data.json?; 882)
[2024-03-19T16:05:49.842+0000] {local_task_job_runner.py:234} INFO - Task exited with return code 1
[2024-03-19T16:05:49.855+0000] {taskinstance.py:3312} INFO - 0 downstream tasks scheduled from follow-on schedule check
