[2024-03-19T15:20:38.937+0000] {taskinstance.py:1979} INFO - Dependencies all met for dep_context=non-requeueable deps ti=<TaskInstance: recalls_etl_v1.get_raw_data manual__2024-03-19T15:20:36.366866+00:00 [queued]>
[2024-03-19T15:20:38.952+0000] {taskinstance.py:1979} INFO - Dependencies all met for dep_context=requeueable deps ti=<TaskInstance: recalls_etl_v1.get_raw_data manual__2024-03-19T15:20:36.366866+00:00 [queued]>
[2024-03-19T15:20:38.953+0000] {taskinstance.py:2193} INFO - Starting attempt 1 of 1
[2024-03-19T15:20:38.962+0000] {taskinstance.py:2217} INFO - Executing <Task(PythonOperator): get_raw_data> on 2024-03-19 15:20:36.366866+00:00
[2024-03-19T15:20:38.977+0000] {standard_task_runner.py:60} INFO - Started process 381 to run task
[2024-03-19T15:20:38.979+0000] {standard_task_runner.py:87} INFO - Running: ['***', 'tasks', 'run', 'recalls_etl_v1', 'get_raw_data', 'manual__2024-03-19T15:20:36.366866+00:00', '--job-id', '4', '--raw', '--subdir', 'DAGS_FOLDER/recalls_etl_v1.py', '--cfg-path', '/tmp/tmpcwz6j90c']
[2024-03-19T15:20:38.982+0000] {standard_task_runner.py:88} INFO - Job 4: Subtask get_raw_data
[2024-03-19T15:20:39.036+0000] {task_command.py:423} INFO - Running <TaskInstance: recalls_etl_v1.get_raw_data manual__2024-03-19T15:20:36.366866+00:00 [running]> on host b1b6e0a46fce
[2024-03-19T15:20:39.105+0000] {taskinstance.py:2513} INFO - Exporting env vars: AIRFLOW_CTX_DAG_OWNER='***' AIRFLOW_CTX_DAG_ID='recalls_etl_v1' AIRFLOW_CTX_TASK_ID='get_raw_data' AIRFLOW_CTX_EXECUTION_DATE='2024-03-19T15:20:36.366866+00:00' AIRFLOW_CTX_TRY_NUMBER='1' AIRFLOW_CTX_DAG_RUN_ID='manual__2024-03-19T15:20:36.366866+00:00'
[2024-03-19T15:22:53.474+0000] {taskinstance.py:2731} ERROR - Task failed with exception
Traceback (most recent call last):
  File "/home/airflow/.local/lib/python3.8/site-packages/requests/models.py", line 971, in json
    return complexjson.loads(self.text, **kwargs)
  File "/usr/local/lib/python3.8/json/__init__.py", line 357, in loads
    return _default_decoder.decode(s)
  File "/usr/local/lib/python3.8/json/decoder.py", line 337, in decode
    obj, end = self.raw_decode(s, idx=_w(s, 0).end())
  File "/usr/local/lib/python3.8/json/decoder.py", line 353, in raw_decode
    obj, end = self.scan_once(s, idx)
json.decoder.JSONDecodeError: Unterminated string starting at: line 1 column 2095787 (char 2095786)

During handling of the above exception, another exception occurred:

Traceback (most recent call last):
  File "/home/airflow/.local/lib/python3.8/site-packages/airflow/models/taskinstance.py", line 444, in _execute_task
    result = _execute_callable(context=context, **execute_callable_kwargs)
  File "/home/airflow/.local/lib/python3.8/site-packages/airflow/models/taskinstance.py", line 414, in _execute_callable
    return execute_callable(context=context, **execute_callable_kwargs)
  File "/home/airflow/.local/lib/python3.8/site-packages/airflow/operators/python.py", line 200, in execute
    return_value = self.execute_callable()
  File "/home/airflow/.local/lib/python3.8/site-packages/airflow/operators/python.py", line 217, in execute_callable
    return self.python_callable(*self.op_args, **self.op_kwargs)
  File "/opt/airflow/dags/recalls_etl_v1.py", line 38, in get_recall_data
    response_data = response.json()
  File "/home/airflow/.local/lib/python3.8/site-packages/requests/models.py", line 975, in json
    raise RequestsJSONDecodeError(e.msg, e.doc, e.pos)
requests.exceptions.JSONDecodeError: Unterminated string starting at: line 1 column 2095787 (char 2095786)
[2024-03-19T15:22:53.525+0000] {taskinstance.py:1149} INFO - Marking task as FAILED. dag_id=recalls_etl_v1, task_id=get_raw_data, execution_date=20240319T152036, start_date=20240319T152038, end_date=20240319T152253
[2024-03-19T15:22:53.554+0000] {standard_task_runner.py:107} ERROR - Failed to execute job 4 for task get_raw_data (Unterminated string starting at: line 1 column 2095787 (char 2095786); 381)
[2024-03-19T15:22:53.671+0000] {local_task_job_runner.py:234} INFO - Task exited with return code 1
[2024-03-19T15:22:53.748+0000] {taskinstance.py:3312} INFO - 0 downstream tasks scheduled from follow-on schedule check
